Workbook

Sheet Hoja1
D2: OT 1069 FERNANDA KRAUSS - COCINA CASA AA
B4: FECHA | C4: N° FACTURA | D4: PROVEEDOR | F4: MONTO NETO | G4: IVA | H4: TOTAL | I4: STATUS
B6: Gastos Provisionados PC | H6: =F6-F7 -> -2519962
B7: Material | F7: =SUM(F8:F28) -> 2519962 | G7: =SUM(G8:G28) -> 478792.78 | H7: =SUM(H8:H28) -> 2998754.8
G8: =F8*19% -> 0 | H8: =F8+G8 -> 0
B9: 46083 | C9: 57028 | D9: MADERAS TARAPACA SPA | E9: ROBLE AMERICANO CEPILLADO C4C 5X150X2.7 (CANT.20) | F9: 332940 | G9: =F9*19% -> 63258.6 | H9: =F9+G9 -> 396198.6
B10: 46087 | C10: 220412 | D10: QUINCAMAT | E10: ROLLO ENCHAPE ENCINA 21MM X 50MTS (CANT.02) | F10: =12597*2 -> 25194 | G10: =F10*19% -> 4786.86 | H10: =F10+G10 -> 29980.86
B11: 46093 | C11: 1582260 | D11: DVP, S.A. | E11: KIT CAJON GRASS NOVAPRO ONE BCO ICE BAJO 500 (CANT.13)/KIT CAJON GRASS NOVAPRO ONE BCO ICE ALTO 500 (CANT.3) | F11: 745800 | G11: =F11*19% -> 141702 | H11: =F11+G11 -> 887502
B12: 46093 | C12: 158630 | D12: PROVELCAR | E12: CORREDERAS OCULTA C S 350 M M (CANT. 04) | F12: 32269 | G12: =F12*19% -> 6131.11 | H12: =F12+G12 -> 38400.11
B13: 46094 | C13: 158724 | D13: PROVELCAR | E13: CANASTO NANO 400MM (CANT. 03) | F13: 80647 | G13: =F13*19% -> 15322.93 | H13: =F13+G13 -> 95969.93
B14: 46094 | C14: 20054608 | D14: IMPERIAL | E14: MELAMINA MDP VALLE NM 18MM 1.83X2.50 (CANT. 02)/ROLLO TAPACANTO PVC VALLE 22X0,45MM RO 25MT (CANT. 01) | F14: 116807 | G14: =F14*19% -> 22193.33 | H14: =F14+G14 -> 139000.33
B15: 46099 | C15: 221221 | D15: QUINCAMAT | E15: TAPACANTO PVC VALLE 21X0,4 (CANT.25MTS) | F15: 6093 | G15: =F15*19% -> 1157.67 | H15: =F15+G15 -> 7250.67
B16: 46099 | C16: 13537 | D16: EPA | E16: AGLOM.ENCINA/ENCINA 15MM (CANT.10)/MDF ENCINA/ENCINA 15MM (CANT.02) | F16: =519970+117432 -> 637402 | G16: =F16*19% -> 121106.38 | H16: =F16+G16 -> 758508.38
B17: 46112 | C17: 20099773 | D17: IMPERIAL | E17: CESTA EXT. 3 NIVELES P/MUEBLE C/S 30CMS KUTZ (CANT.01) | F17: 29403 | G17: =F17*19% -> 5586.57 | H17: =F17+G17 -> 34989.57
B18: 46113 | C18: 304046 | D18: HBT | E18: MANILLA TUCSON CAFÉ ANTIQU 160MM (CANT.40)/MANILLA CE NEGRO MATE 160/200MM (CANT. 07) | F18: 134578 | G18: =F18*19% -> 25569.82 | H18: =F18+G18 -> 160147.82
B19: 46114 | C19: 160228 | D19: PROVELCAR | E19: BASURERO BAJO LAVAPLATOS DOBLE (CANT.01) | F19: 46210 | G19: =F19*19% -> 8779.9 | H19: =F19+G19 -> 54989.9
B20: 46128 | C20: 35313 | D20: FORMAS WOOD | E20: CHAPA ENCINA ROJA PRIMERA 39X270X2 (CANT. 02) | F20: 14322 | G20: =F20*19% -> 2721.18 | H20: =F20+G20 -> 17043.18
B21: 46157 | C21: 78149 | D21: DPH HERRAJES | E21: ESPECIERO ANTRACITA DPH CIERRE SUAVE 300MM (CANT.01) | F21: 41597 | G21: =F21*19% -> 7903.43 | H21: =F21+G21 -> 49500.43
B22: 46161 | C22: 224810 | D22: QUINCAMAT | E22: CANTO PVC ACACIA 22 X 0.44 X 50MTS (CANT.01) | F22: 12605 | G22: =F22*19% -> 2394.95 | H22: =F22+G22 -> 14999.95
B23: 46168 | C23: 1663971 | D23: DAP DUCASSE DISEÑO LTDA | E23: TIRADORES POMO 25X21MM (CANT. 06) | F23: 15054 | G23: =F23*19% -> 2860.26 | H23: =F23+G23 -> 17914.26
B24: 46168 | C24: 1659300 | D24: DAP DUCASSE DISEÑO LTDA | E24: TIRADORES POMO 25X21MM (CANT. 06) | F24: 15054 | G24: =F24*19% -> 2860.26 | H24: =F24+G24 -> 17914.26
B25: 46190 | C25: 1659765 | D25: DAP DUCASSE DISEÑO LTDA | E25: TIRADORES POMO 25X21MM (CANT. 03) | F25: 7527 | G25: =F25*19% -> 1430.13 | H25: =F25+G25 -> 8957.13
D27: HBT | E27: BISAGRA RECTA CIERRE SUAVE CLIPTOP 110° UNID (CANT 67) STOCK FABRICA | F27: =2880*67 -> 192960 | G27: =F27*19% -> 36662.4 | H27: =F27+G27 -> 229622.4
D28: HBT | E28: PLANCHETA CLIPTOP EN CRUZ 5mm (CANT 67) STOCK FABRICA | F28: =500*67 -> 33500 | G28: =F28*19% -> 6365 | H28: =F28+G28 -> 39865
B30: Gastos Provisionados PC | H30: =F30-F31 -> -212011
B31: Electricidad | F31: =SUM(F32:F36) -> 212011 | G31: =SUM(G32:G36) -> 40282.09 | H31: =SUM(H32:H36) -> 252293.09
G32: =F32*19% -> 0 | H32: =F32+G32 -> 0
B33: 46097 | C33: 241121 | D33: LED STUDIO | E33: PERFIL PARA CINTA LED STUDIO EMBUTIDO PLANO 2 MTS NEGRO (CANT. 08) | F33: 53849 | G33: =F33*19% -> 10231.31 | H33: =F33+G33 -> 64080.31
B34: 46098 | C34: 36350 | D34: ASYCAR | E34: FUENTE DE PODER 23W 12V INTERIOR (CANT.01)/FUENTE DE PODER 50W 12V INTERIOR (CANT.01)/FUENTE DE PODER 75W 12V INTERIOR (CANT.01)/CINTA LED 2835 BCO CALIDO 9.6W 12V (CANT.15MTS) | F34: 97718 | G34: =F34*19% -> 18566.42 | H34: =F34+G34 -> 116284.42
B35: 46162 | C35: 247538 | D35: LED STUDIO | E35: PERFIL PARA CINTA LED STUDIO EMBUTIDO PLANO 2 MTS NEGRO (CANT. 08) | F35: 60444 | G35: =F35*19% -> 11484.36 | H35: =F35+G35 -> 71928.36
G36: =F36*19% -> 0 | H36: =F36+G36 -> 0
B37: Gastos Provisionados PC | H37: =F37-F38 -> -236952
B38: Pintura y Derivados | F38: =SUM(F39:F46) -> 236952 | G38: =SUM(G39:G46) -> 45020.88 | H38: =SUM(H39:H46) -> 281972.88
G39: =F39*19% -> 0 | H39: =F39+G39 -> 0
B40: 46076 | C40: 147752 | D40: ENKO CHILE | E40: APLICACIÓN TINTA O ACEITE C/ESTANDAR C/ACABADO | F40: 38700 | G40: =F40*19% -> 7353 | H40: =F40+G40 -> 46053 | I40: MUESTRAS
B41: 46090 | C41: 148419 | D41: ENKO CHILE | E41: DESARROLLO DE COLOR LACADO,TINTA,ACEITE Y OTROS | F41: 53700 | G41: =F41*19% -> 10203 | H41: =F41+G41 -> 63903 | I41: MUESTRAS
B42: 46113 | C42: 149563 | D42: ENKO CHILE | E42: DILUYENTE PU UNIVERSAL (CANT. 15LT) | F42: 51570 | G42: =F42*19% -> 9798.3 | H42: =F42+G42 -> 61368.3
B43: 46118 | C43: 149662 | D43: ENKO CHILE | E43: DESARROLLO DE COLOR LACADO,TINTA,ACEITE Y OTROS ZZLAB.T3 (CANT. 1UND) | F43: 17900 | G43: =F43*19% -> 3401 | H43: =F43+G43 -> 21301
B44: 46125 | C44: 149976 | D44: ENKO CHILE | E44: TINTA AQUALINE B/AGUA LISTA USO NOGAL EUROPEO(CANT.1LT) | F44: 5789 | G44: =F44*19% -> 1099.91 | H44: =F44+G44 -> 6888.91
B45: 46126 | C45: 150058 | D45: ENKO CHILE | E45: TINTA AQUALINE LISTA USO (CANT.20LT) | F45: 69293 | G45: =F45*19% -> 13165.67 | H45: =F45+G45 -> 82458.67
...

Sheet Análisis Proyecto
A1: ANÁLISIS FINANCIERO · OT 1069
A2: Fernanda Krauss · Cocina Casa AA | análisis neto, vinculado a Hoja1
A4: INGRESO NETO | C4: COSTO REAL | E4: UTILIDAD REAL | G4: MARGEN REAL
A5: =Hoja1!C81 -> 29869454 | C5: =Hoja1!E91 -> 11537116 | E5: =Hoja1!C81-Hoja1!E91 -> 18332338 | G5: =(Hoja1!C81-Hoja1!E91)/Hoja1!C81 -> 0.61374869
A8: PRESUPUESTO DE COSTOS | C8: AHORRO VS PC | E8: DESVIACIÓN FAVORABLE | G8: UTILIDAD MOSTRADA EN FUENTE
A9: =SUM(Hoja1!C86:C90) -> 20521040 | C9: =SUM(Hoja1!C86:C90)-Hoja1!E91 -> 8983924.3 | E9: =(SUM(Hoja1!C86:C90)-Hoja1!E91)/SUM(Hoja1!C86:C90) -> 0.43779089 | G9: =Hoja1!H91 -> 11393364
A11: DESEMPEÑO POR CATEGORÍA
A12: Categoría | B12: PC | C12: Real | D12: Variación $ | E12: Variación % | F12: Estado
A13: Materiales | B13: =Hoja1!C86 -> 8868219 | C13: =Hoja1!E86 -> 3184965 | D13: =B13-C13 -> 5683254 | E13: =IFERROR(D13/B13,0) -> 0.6408563 | F13: =IF(D13>=0,"Favorable","Sobrecosto") -> Favorable
A14: Mano de obra | B14: =Hoja1!C87 -> 4085000 | C14: =Hoja1!E87 -> 3016750 | D14: =B14-C14 -> 1068250 | E14: =IFERROR(D14/B14,0) -> 0.26150551 | F14: =IF(D14>=0,"Favorable","Sobrecosto") -> Favorable
A15: Instalación | B15: =Hoja1!C88 -> 1915000 | C15: =Hoja1!E88 -> 1215000 | D15: =B15-C15 -> 700000 | E15: =IFERROR(D15/B15,0) -> 0.36553525 | F15: =IF(D15>=0,"Favorable","Sobrecosto") -> Favorable
A16: Mano de obra externa | B16: =Hoja1!C89 -> 4766819 | C16: =Hoja1!E89 -> 3071572 | D16: =B16-C16 -> 1695247 | E16: =IFERROR(D16/B16,0) -> 0.35563486 | F16: =IF(D16>=0,"Favorable","Sobrecosto") -> Favorable
A17: Gastos administrativos | B17: =Hoja1!C90 -> 886002 | C17: =Hoja1!E90 -> 1048828.7 | D17: =B17-C17 -> -162826.7 | E17: =IFERROR(D17/B17,0) -> -0.1837769 | F17: =IF(D17>=0,"Favorable","Sobrecosto") -> Sobrecosto
A18: TOTAL | B18: =SUM(B13:B17) -> 20521040 | C18: =SUM(C13:C17) -> 11537116 | D18: =B18-C18 -> 8983924.3 | E18: =IFERROR(D18/B18,0) -> 0.43779089 | F18: =IF(D18>=0,"Favorable","Sobrecosto") -> Favorable
A21: CONTROL DOCUMENTAL
A22: Indicador | B22: Resultado | D22: Indicador | E22: Resultado
A23: Movimientos detallados | B23: =COUNTIF(Hoja1!F9:F28,">0")+COUNTIF(Hoja1!F33:F35,">0")+COUNTIF(Hoja1!F40:F45,">0")+COUNTIF(Hoja1!F49:F51,">0")+COUNTIF(Hoja1!F67:F69,">0") -> 34 | D23: Cobertura fecha | E23: =IFERROR(B24/B23,0) -> 0.85294118
A24: Con fecha | B24: =COUNT(Hoja1!B9:B28)+COUNT(Hoja1!B33:B35)+COUNT(Hoja1!B40:B45)+COUNT(Hoja1!B49:B51)+COUNT(Hoja1!B67:B69) -> 29 | D24: Cobertura factura | E24: =IFERROR(B25/B23,0) -> 0.85294118
A25: Con N° factura | B25: =COUNT(Hoja1!C9:C28)+COUNT(Hoja1!C33:C35)+COUNT(Hoja1!C40:C45)+COUNT(Hoja1!C49:C51)+COUNT(Hoja1!C67:C69) -> 29 | D25: Cobertura status | E25: =IFERROR(B26/B23,0) -> 0.058823529
A26: Con status | B26: =COUNTA(Hoja1!I9:I28)+COUNTA(Hoja1!I33:I35)+COUNTA(Hoja1!I40:I45)+COUNTA(Hoja1!I49:I51)+COUNTA(Hoja1!I67:I69) -> 2 | D26: Muestras incluidas (neto) | E26: =SUM(Hoja1!F40:F41) -> 92400
A29: HALLAZGOS CLAVE
A30: 1. Utilidad corregida: Hoja1!H91 no incorpora los $6.938.974 cobrados por mano de obra externa.
A31: 2. Costos reales 43,8% bajo PC; materiales explican $5.683.254 del ahorro total.
A32: 3. Gastos administrativos exceden el PC en $162.827 (+18,4%); es la única categoría desfavorable.
A33: 4. Solo 2 de 34 movimientos tienen STATUS; 5 movimientos de stock no tienen fecha ni N° de factura.
A34: 5. $92.400 netos de muestras están incluidos en Pintura; conviene validar si son imputables al proyecto.
